Workbook

Sheet Input
B1: ACSS Open Data Assesment Tools
B2: Please only fill columns F, N, O, P, Q, R, T and U. The rest of cells will be auto-generated. | E2: Reference Year: | F2: 2021
A3: Code | B3: Section | C3: Category | D3: Indicator | E3: Disaggregation (^ is for ASEAN Only) | F3: Series of data availability Separate years by comma, i.e: 2010, 2017,2018 if 0 number of years are available, leave blank if indicator is not applicable, indicate NA | G3: Count of any years | H3: Count of last 5 Years | I3: Count of last 10 Years | J3: Coverage: Data availability/published for public [C] | N3: Openenness [O] | T3: URL(s) containing respective datasets assessed | U3: Remarks
J4: At least one year [C1] | K4: AT least 3 of the last 5 years [C2] | L4: At least 6 of the last 10 years [C3] | M4: Coverage Sub Score [C1] + [C2] +C3] | N4: Machine Readability [O1] 1 or 0 point | O4: Non Proprietary [O2] 1 or 0 point | P4: Download Options [O3] 1 or 0.5 or 0 point | Q4: Metadata Availability [O4] 1 or 0,5 or 0 point | R4: Term of Use [O5] 1 or 0.5 or 0 point | S4: Openness Sub Score [O1] + [O2] + [03]
A5: SO.POV.POV.001 | B5: Socio-Demography | C5: Poverty | D5: Proportion of Population Living below National Poverty Line (2) | E5: i. Total | G5: =IF(LEN(TRIM(F5)) = 4, 1, IF(LEN(TRIM(F5)) > 5, LEN(TRIM(F5))-LEN(SUBSTITUTE(TRIM(F5),",",""))+1, 0)) -> 0 | H5: =IF(ISNUMBER(SEARCH($F$2, $F5)), 1, 0) + IF(ISNUMBER(SEARCH($F$2-1, $F5)), 1, 0) + IF(ISNUMBER(SEARCH($F$2-2, $F5)), 1, 0) + IF(ISNUMBER(SEARCH($F$2-3, $F5)), 1, 0) + IF(ISNUMBER(SEARCH($F$2-4, $F5)), 1, 0) -> 0 | I5: =IF(ISNUMBER(SEARCH($F$2, $F5)), 1, 0) + IF(ISNUMBER(SEARCH($F$2-1, $F5)), 1, 0) + IF(ISNUMBER(SEARCH($F$2-2, $F5)), 1, 0) + IF(ISNUMBER(SEARCH($F$2-3, $F5)), 1, 0) + IF(ISNUMBER(SEARCH($F$2-4, $F5)), 1, 0) + IF(ISNUMBER(SEARCH($F$2-5, $F5)), 1, 0) + IF(ISNUMBER(SEARCH($F$2-6, $F5)), 1, 0) + IF(ISNUMBER(SEARCH($F$2-7, $F5)), 1, 0) + IF(ISNUMBER(SEARCH($F$2-8, $F5)), 1, 0) + IF(ISNUMBER(SEARCH($F$2-9, $F5)), 1, 0) -> 0 | J5: =IF(F5="NA", "NA", IF(G5>0, 1, 0)) -> 0 | K5: =IF(F5="NA","NA",IF(H5>2,1,IF(H5>1,0.5,0))) -> 0 | L5: =IF(F5="NA","NA",IF(I5>5, 1, IF(I5>2, 0.5, 0))) -> 0 | M5: =SUMIF(J5:L5,"<>#N/A") -> 0 | N5: =IF(F5 = "NA", "NA", 0) -> 0 | O5: =IF(F5 = "NA", "NA", 0) -> 0 | P5: =IF(F5 = "NA", "NA", 0) -> 0 | Q5: =IF(F5 = "NA", "NA", 0) -> 0 | R5: =IF(F5 = "NA", "NA", 0) -> 0 | S5: =SUMIF(N5:R5,"<>#N/A") -> 0
A6: SO.POV.POV.002 | E6: ii. By Sex | G6: =IF(LEN(TRIM(F6)) = 4, 1, IF(LEN(TRIM(F6)) > 5, LEN(TRIM(F6))-LEN(SUBSTITUTE(TRIM(F6),",",""))+1, 0)) -> 0 | H6: =IF(ISNUMBER(SEARCH($F$2, $F6)), 1, 0) + IF(ISNUMBER(SEARCH($F$2-1, $F6)), 1, 0) + IF(ISNUMBER(SEARCH($F$2-2, $F6)), 1, 0) + IF(ISNUMBER(SEARCH($F$2-3, $F6)), 1, 0) + IF(ISNUMBER(SEARCH($F$2-4, $F6)), 1, 0) -> 0 | I6: =IF(ISNUMBER(SEARCH($F$2, $F6)), 1, 0) + IF(ISNUMBER(SEARCH($F$2-1, $F6)), 1, 0) + IF(ISNUMBER(SEARCH($F$2-2, $F6)), 1, 0) + IF(ISNUMBER(SEARCH($F$2-3, $F6)), 1, 0) + IF(ISNUMBER(SEARCH($F$2-4, $F6)), 1, 0) + IF(ISNUMBER(SEARCH($F$2-5, $F6)), 1, 0) + IF(ISNUMBER(SEARCH($F$2-6, $F6)), 1, 0) + IF(ISNUMBER(SEARCH($F$2-7, $F6)), 1, 0) + IF(ISNUMBER(SEARCH($F$2-8, $F6)), 1, 0) + IF(ISNUMBER(SEARCH($F$2-9, $F6)), 1, 0) -> 0 | J6: =IF(F6="NA", "NA", IF(G6>0, 1, 0)) -> 0 | K6: =IF(F6="NA","NA",IF(H6>2,1,IF(H6>1,0.5,0))) -> 0 | L6: =IF(F6="NA","NA",IF(I6>5, 1, IF(I6>2, 0.5, 0))) -> 0 | M6: =SUMIF(J6:L6,"<>#N/A") -> 0 | N6: =IF(F6 = "NA", "NA", 0) -> 0 | O6: =IF(F6 = "NA", "NA", 0) -> 0 | P6: =IF(F6 = "NA", "NA", 0) -> 0 | Q6: =IF(F6 = "NA", "NA", 0) -> 0 | R6: =IF(F6 = "NA", "NA", 0) -> 0 | S6: =SUMIF(N6:R6,"<>#N/A") -> 0
A7: SO.POV.IND.003 | D7: Income Distribution (1) | E7: Decile or Quintile | G7: =IF(LEN(TRIM(F7)) = 4, 1, IF(LEN(TRIM(F7)) > 5, LEN(TRIM(F7))-LEN(SUBSTITUTE(TRIM(F7),",",""))+1, 0)) -> 0 | H7: =IF(ISNUMBER(SEARCH($F$2, $F7)), 1, 0) + IF(ISNUMBER(SEARCH($F$2-1, $F7)), 1, 0) + IF(ISNUMBER(SEARCH($F$2-2, $F7)), 1, 0) + IF(ISNUMBER(SEARCH($F$2-3, $F7)), 1, 0) + IF(ISNUMBER(SEARCH($F$2-4, $F7)), 1, 0) -> 0 | I7: =IF(ISNUMBER(SEARCH($F$2, $F7)), 1, 0) + IF(ISNUMBER(SEARCH($F$2-1, $F7)), 1, 0) + IF(ISNUMBER(SEARCH($F$2-2, $F7)), 1, 0) + IF(ISNUMBER(SEARCH($F$2-3, $F7)), 1, 0) + IF(ISNUMBER(SEARCH($F$2-4, $F7)), 1, 0) + IF(ISNUMBER(SEARCH($F$2-5, $F7)), 1, 0) + IF(ISNUMBER(SEARCH($F$2-6, $F7)), 1, 0) + IF(ISNUMBER(SEARCH($F$2-7, $F7)), 1, 0) + IF(ISNUMBER(SEARCH($F$2-8, $F7)), 1, 0) + IF(ISNUMBER(SEARCH($F$2-9, $F7)), 1, 0) -> 0 | J7: =IF(F7="NA", "NA", IF(G7>0, 1, 0)) -> 0 | K7: =IF(F7="NA","NA",IF(H7>2,1,IF(H7>1,0.5,0))) -> 0 | L7: =IF(F7="NA","NA",IF(I7>5, 1, IF(I7>2, 0.5, 0))) -> 0 | M7: =SUMIF(J7:L7,"<>#N/A") -> 0 | N7: =IF(F7 = "NA", "NA", 0) -> 0 | O7: =IF(F7 = "NA", "NA", 0) -> 0 | P7: =IF(F7 = "NA", "NA", 0) -> 0 | Q7: =IF(F7 = "NA", "NA", 0) -> 0 | R7: =IF(F7 = "NA", "NA", 0) -> 0 | S7: =SUMIF(N7:R7,"<>#N/A") -> 0
A8: SO.POV.GIN.000 | D8: Gini Coefficient (1) | G8: =IF(LEN(TRIM(F8)) = 4, 1, IF(LEN(TRIM(F8)) > 5, LEN(TRIM(F8))-LEN(SUBSTITUTE(TRIM(F8),",",""))+1, 0)) -> 0 | H8: =IF(ISNUMBER(SEARCH($F$2, $F8)), 1, 0) + IF(ISNUMBER(SEARCH($F$2-1, $F8)), 1, 0) + IF(ISNUMBER(SEARCH($F$2-2, $F8)), 1, 0) + IF(ISNUMBER(SEARCH($F$2-3, $F8)), 1, 0) + IF(ISNUMBER(SEARCH($F$2-4, $F8)), 1, 0) -> 0 | I8: =IF(ISNUMBER(SEARCH($F$2, $F8)), 1, 0) + IF(ISNUMBER(SEARCH($F$2-1, $F8)), 1, 0) + IF(ISNUMBER(SEARCH($F$2-2, $F8)), 1, 0) + IF(ISNUMBER(SEARCH($F$2-3, $F8)), 1, 0) + IF(ISNUMBER(SEARCH($F$2-4, $F8)), 1, 0) + IF(ISNUMBER(SEARCH($F$2-5, $F8)), 1, 0) + IF(ISNUMBER(SEARCH($F$2-6, $F8)), 1, 0) + IF(ISNUMBER(SEARCH($F$2-7, $F8)), 1, 0) + IF(ISNUMBER(SEARCH($F$2-8, $F8)), 1, 0) + IF(ISNUMBER(SEARCH($F$2-9, $F8)), 1, 0) -> 0 | J8: =IF(F8="NA", "NA", IF(G8>0, 1, 0)) -> 0 | K8: =IF(F8="NA","NA",IF(H8>2,1,IF(H8>1,0.5,0))) -> 0 | L8: =IF(F8="NA","NA",IF(I8>5, 1, IF(I8>2, 0.5, 0))) -> 0 | M8: =SUMIF(J8:L8,"<>#N/A") -> 0 | N8: =IF(F8 = "NA", "NA", 0) -> 0 | O8: =IF(F8 = "NA", "NA", 0) -> 0 | P8: =IF(F8 = "NA", "NA", 0) -> 0 | Q8: =IF(F8 = "NA", "NA", 0) -> 0 | R8: =IF(F8 = "NA", "NA", 0) -> 0 | S8: =SUMIF(N8:R8,"<>#N/A") -> 0
A9: SO.POP.POP.001 | C9: Population | D9: Population (4) | E9: i. Total | G9: =IF(LEN(TRIM(F9)) = 4, 1, IF(LEN(TRIM(F9)) > 5, LEN(TRIM(F9))-LEN(SUBSTITUTE(TRIM(F9),",",""))+1, 0)) -> 0 | H9: =IF(ISNUMBER(SEARCH($F$2, $F9)), 1, 0) + IF(ISNUMBER(SEARCH($F$2-1, $F9)), 1, 0) + IF(ISNUMBER(SEARCH($F$2-2, $F9)), 1, 0) + IF(ISNUMBER(SEARCH($F$2-3, $F9)), 1, 0) + IF(ISNUMBER(SEARCH($F$2-4, $F9)), 1, 0) -> 0 | I9: =IF(ISNUMBER(SEARCH($F$2, $F9)), 1, 0) + IF(ISNUMBER(SEARCH($F$2-1, $F9)), 1, 0) + IF(ISNUMBER(SEARCH($F$2-2, $F9)), 1, 0) + IF(ISNUMBER(SEARCH($F$2-3, $F9)), 1, 0) + IF(ISNUMBER(SEARCH($F$2-4, $F9)), 1, 0) + IF(ISNUMBER(SEARCH($F$2-5, $F9)), 1, 0) + IF(ISNUMBER(SEARCH($F$2-6, $F9)), 1, 0) + IF(ISNUMBER(SEARCH($F$2-7, $F9)), 1, 0) + IF(ISNUMBER(SEARCH($F$2-8, $F9)), 1, 0) + IF(ISNUMBER(SEARCH($F$2-9, $F9)), 1, 0) -> 0 | J9: =IF(F9="NA", "NA", IF(G9>0, 1, 0)) -> 0 | K9: =IF(F9="NA","NA",IF(H9>2,1,IF(H9>1,0.5,0))) -> 0 | L9: =IF(F9="NA","NA",IF(I9>5, 1, IF(I9>2, 0.5, 0))) -> 0 | M9: =SUMIF(J9:L9,"<>#N/A") -> 0 | N9: 0 | O9: 0 | P9: =IF(F9 = "NA", "NA", 0) -> 0 | Q9: =IF(F9 = "NA", "NA", 0) -> 0 | R9: =IF(F9 = "NA", "NA", 0) -> 0 | S9: =SUMIF(N9:R9,"<>#N/A") -> 0
A10: SO.POP.POP.002 | E10: ii. By Sex | G10: =IF(LEN(TRIM(F10)) = 4, 1, IF(LEN(TRIM(F10)) > 5, LEN(TRIM(F10))-LEN(SUBSTITUTE(TRIM(F10),",",""))+1, 0)) -> 0 | H10: =IF(ISNUMBER(SEARCH($F$2, $F10)), 1, 0) + IF(ISNUMBER(SEARCH($F$2-1, $F10)), 1, 0) + IF(ISNUMBER(SEARCH($F$2-2, $F10)), 1, 0) + IF(ISNUMBER(SEARCH($F$2-3, $F10)), 1, 0) + IF(ISNUMBER(SEARCH($F$2-4, $F10)), 1, 0) -> 0 | I10: =IF(ISNUMBER(SEARCH($F$2, $F10)), 1, 0) + IF(ISNUMBER(SEARCH($F$2-1, $F10)), 1, 0) + IF(ISNUMBER(SEARCH($F$2-2, $F10)), 1, 0) + IF(ISNUMBER(SEARCH($F$2-3, $F10)), 1, 0) + IF(ISNUMBER(SEARCH($F$2-4, $F10)), 1, 0) + IF(ISNUMBER(SEARCH($F$2-5, $F10)), 1, 0) + IF(ISNUMBER(SEARCH($F$2-6, $F10)), 1, 0) + IF(ISNUMBER(SEARCH($F$2-7, $F10)), 1, 0) + IF(ISNUMBER(SEARCH($F$2-8, $F10)), 1, 0) + IF(ISNUMBER(SEARCH($F$2-9, $F10)), 1, 0) -> 0 | J10: =IF(F10="NA", "NA", IF(G10>0, 1, 0)) -> 0 | K10: =IF(F10="NA","NA",IF(H10>2,1,IF(H10>1,0.5,0))) -> 0 | L10: =IF(F10="NA","NA",IF(I10>5, 1, IF(I10>2, 0.5, 0))) -> 0 | M10: =SUMIF(J10:L10,"<>#N/A") -> 0 | N10: =IF(F10 = "NA", "NA", 0) -> 0 | O10: =IF(F10 = "NA", "NA", 0) -> 0 | P10: =IF(F10 = "NA", "NA", 0) -> 0 | Q10: =IF(F10 = "NA", "NA", 0) -> 0 | R10: =IF(F10 = "NA", "NA", 0) -> 0 | S10: =SUMIF(N10:R10,"<>#N/A") -> 0
A11: SO.POP.POP.004 | E11: iii. By Age Group | G11: =IF(LEN(TRIM(F11)) = 4, 1, IF(LEN(TRIM(F11)) > 5, LEN(TRIM(F11))-LEN(SUBSTITUTE(TRIM(F11),",",""))+1, 0)) -> 0 | H11: =IF(ISNUMBER(SEARCH($F$2, $F11)), 1, 0) + IF(ISNUMBER(SEARCH($F$2-1, $F11)), 1, 0) + IF(ISNUMBER(SEARCH($F$2-2, $F11)), 1, 0) + IF(ISNUMBER(SEARCH($F$2-3, $F11)), 1, 0) + IF(ISNUMBER(SEARCH($F$2-4, $F11)), 1, 0) -> 0 | I11: =IF(ISNUMBER(SEARCH($F$2, $F11)), 1, 0) + IF(ISNUMBER(SEARCH($F$2-1, $F11)), 1, 0) + IF(ISNUMBER(SEARCH($F$2-2, $F11)), 1, 0) + IF(ISNUMBER(SEARCH($F$2-3, $F11)), 1, 0) + IF(ISNUMBER(SEARCH($F$2-4, $F11)), 1, 0) + IF(ISNUMBER(SEARCH($F$2-5, $F11)), 1, 0) + IF(ISNUMBER(SEARCH($F$2-6, $F11)), 1, 0) + IF(ISNUMBER(SEARCH($F$2-7, $F11)), 1, 0) + IF(ISNUMBER(SEARCH($F$2-8, $F11)), 1, 0) + IF(ISNUMBER(SEARCH($F$2-9, $F11)), 1, 0) -> 0 | J11: =IF(F11="NA", "NA", IF(G11>0, 1, 0)) -> 0 | K11: =IF(F11="NA","NA",IF(H11>2,1,IF(H11>1,0.5,0))) -> 0 | L11: =IF(F11="NA","NA",IF(I11>5, 1, IF(I11>2, 0.5, 0))) -> 0 | M11: =SUMIF(J11:L11,"<>#N/A") -> 0 | N11: =IF(F11 = "NA", "NA", 0) -> 0 | O11: =IF(F11 = "NA", "NA", 0) -> 0 | P11: =IF(F11 = "NA", "NA", 0) -> 0 | Q11: =IF(F11 = "NA", "NA", 0) -> 0 | R11: =IF(F11 = "NA", "NA", 0) -> 0 | S11: =SUMIF(N11:R11,"<>#N/A") -> 0
A12: SO.POP.POP.005 | E12: iv. By Urban/ Rural/ Slums | G12: =IF(LEN(TRIM(F12)) = 4, 1, IF(LEN(TRIM(F12)) > 5, LEN(TRIM(F12))-LEN(SUBSTITUTE(TRIM(F12),",",""))+1, 0)) -> 0 | H12: =IF(ISNUMBER(SEARCH($F$2, $F12)), 1, 0) + IF(ISNUMBER(SEARCH($F$2-1, $F12)), 1, 0) + IF(ISNUMBER(SEARCH($F$2-2, $F12)), 1, 0) + IF(ISNUMBER(SEARCH($F$2-3, $F12)), 1, 0) + IF(ISNUMBER(SEARCH($F$2-4, $F12)), 1, 0) -> 0 | I12: =IF(ISNUMBER(SEARCH($F$2, $F12)), 1, 0) + IF(ISNUMBER(SEARCH($F$2-1, $F12)), 1, 0) + IF(ISNUMBER(SEARCH($F$2-2, $F12)), 1, 0) + IF(ISNUMBER(SEARCH($F$2-3, $F12)), 1, 0) + IF(ISNUMBER(SEARCH($F$2-4, $F12)), 1, 0) + IF(ISNUMBER(SEARCH($F$2-5, $F12)), 1, 0) + IF(ISNUMBER(SEARCH($F$2-6, $F12)), 1, 0) + IF(ISNUMBER(SEARCH($F$2-7, $F12)), 1, 0) + IF(ISNUMBER(SEARCH($F$2-8, $F12)), 1, 0) + IF(ISNUMBER(SEARCH($F$2-9, $F12)), 1, 0) -> 0 | J12: =IF(F12="NA", "NA", IF(G12>0, 1, 0)) -> 0 | K12: =IF(F12="NA","NA",IF(H12>2,1,IF(H12>1,0.5,0))) -> 0 | L12: =IF(F12="NA","NA",IF(I12>5, 1, IF(I12>2, 0.5, 0))) -> 0 | M12: =SUMIF(J12:L12,"<>#N/A") -> 0 | N12: =IF(F12 = "NA", "NA", 0) -> 0 | O12: =IF(F12 = "NA", "NA", 0) -> 0 | P12: =IF(F12 = "NA", "NA", 0) -> 0 | Q12: =IF(F12 = "NA", "NA", 0) -> 0 | R12: =IF(F12 = "NA", "NA", 0) -> 0 | S12: =SUMIF(N12:R12,"<>#N/A") -> 0
A13: SO.POP.PGR.000 | D13: Population Growth Rate (1) | G13: =IF(LEN(TRIM(F13)) = 4, 1, IF(LEN(TRIM(F13)) > 5, LEN(TRIM(F13))-LEN(SUBSTITUTE(TRIM(F13),",",""))+1, 0)) -> 0 | H13: =IF(ISNUMBER(SEARCH($F$2, $F13)), 1, 0) + IF(ISNUMBER(SEARCH($F$2-1, $F13)), 1, 0) + IF(ISNUMBER(SEARCH($F$2-2, $F13)), 1, 0) + IF(ISNUMBER(SEARCH($F$2-3, $F13)), 1, 0) + IF(ISNUMBER(SEARCH($F$2-4, $F13)), 1, 0) -> 0 | I13: =IF(ISNUMBER(SEARCH($F$2, $F13)), 1, 0) + IF(ISNUMBER(SEARCH($F$2-1, $F13)), 1, 0) + IF(ISNUMBER(SEARCH($F$2-2, $F13)), 1, 0) + IF(ISNUMBER(SEARCH($F$2-3, $F13)), 1, 0) + IF(ISNUMBER(SEARCH($F$2-4, $F13)), 1, 0) + IF(ISNUMBER(SEARCH($F$2-5, $F13)), 1, 0) + IF(ISNUMBER(SEARCH($F$2-6, $F13)), 1, 0) + IF(ISNUMBER(SEARCH($F$2-7, $F13)), 1, 0) + IF(ISNUMBER(SEARCH($F$2-8, $F13)), 1, 0) + IF(ISNUMBER(SEARCH($F$2-9, $F13)), 1, 0) -> 0 | J13: =IF(F13="NA", "NA", IF(G13>0, 1, 0)) -> 0 | K13: =IF(F13="NA","NA",IF(H13>2,1,IF(H13>1,0.5,0))) -> 0 | L13: =IF(F13="NA","NA",IF(I13>5, 1, IF(I13>2, 0.5, 0))) -> 0 | M13: =SUMIF(J13:L13,"<>#N/A") -> 0 | N13: =IF(F13 = "NA", "NA", 0) -> 0 | O13: =IF(F13 = "NA", "NA", 0) -> 0 | P13: =IF(F13 = "NA", "NA", 0) -> 0 | Q13: =IF(F13 = "NA", "NA", 0) -> 0 | R13: =IF(F13 = "NA", "NA", 0) -> 0 | S13: =SUMIF(N13:R13,"<>#N/A") -> 0
A14: SO.POP.PPD.000 | D14: Population Density (1) | G14: =IF(LEN(TRIM(F14)) = 4, 1, IF(LEN(TRIM(F14)) > 5, LEN(TRIM(F14))-LEN(SUBSTITUTE(TRIM(F14),",",""))+1, 0)) -> 0 | H14: =IF(ISNUMBER(SEARCH($F$2, $F14)), 1, 0) + IF(ISNUMBER(SEARCH($F$2-1, $F14)), 1, 0) + IF(ISNUMBER(SEARCH($F$2-2, $F14)), 1, 0) + IF(ISNUMBER(SEARCH($F$2-3, $F14)), 1, 0) + IF(ISNUMBER(SEARCH($F$2-4, $F14)), 1, 0) -> 0 | I14: =IF(ISNUMBER(SEARCH($F$2, $F14)), 1, 0) + IF(ISNUMBER(SEARCH($F$2-1, $F14)), 1, 0) + IF(ISNUMBER(SEARCH($F$2-2, $F14)), 1, 0) + IF(ISNUMBER(SEARCH($F$2-3, $F14)), 1, 0) + IF(ISNUMBER(SEARCH($F$2-4, $F14)), 1, 0) + IF(ISNUMBER(SEARCH($F$2-5, $F14)), 1, 0) + IF(ISNUMBER(SEARCH($F$2-6, $F14)), 1, 0) + IF(ISNUMBER(SEARCH($F$2-7, $F14)), 1, 0) + IF(ISNUMBER(SEARCH($F$2-8, $F14)), 1, 0) + IF(ISNUMBER(SEARCH($F$2-9, $F14)), 1, 0) -> 0 | J14: =IF(F14="NA", "NA", IF(G14>0, 1, 0)) -> 0 | K14: =IF(F14="NA","NA",IF(H14>2,1,IF(H14>1,0.5,0))) -> 0 | L14: =IF(F14="NA","NA",IF(I14>5, 1, IF(I14>2, 0.5, 0))) -> 0 | M14: =SUMIF(J14:L14,"<>#N/A") -> 0 | N14: =IF(F14 = "NA", "NA", 0) -> 0 | O14: =IF(F14 = "NA", "NA", 0) -> 0 | P14: =IF(F14 = "NA", "NA", 0) -> 0 | Q14: =IF(F14 = "NA", "NA", 0) -> 0 | R14: =IF(F14 = "NA", "NA", 0) -> 0 | S14: =SUMIF(N14:R14,"<>#N/A") -> 0
A15: SO.HEW.TFR.000 | C15: Health and Well-Being | D15: Total Fertility Rate (1) | G15: =IF(LEN(TRIM(F15)) = 4, 1, IF(LEN(TRIM(F15)) > 5, LEN(TRIM(F15))-LEN(SUBSTITUTE(TRIM(F15),",",""))+1, 0)) -> 0 | H15: =IF(ISNUMBER(SEARCH($F$2, $F15)), 1, 0) + IF(ISNUMBER(SEARCH($F$2-1, $F15)), 1, 0) + IF(ISNUMBER(SEARCH($F$2-2, $F15)), 1, 0) + IF(ISNUMBER(SEARCH($F$2-3, $F15)), 1, 0) + IF(ISNUMBER(SEARCH($F$2-4, $F15)), 1, 0) -> 0 | I15: =IF(ISNUMBER(SEARCH($F$2, $F15)), 1, 0) + IF(ISNUMBER(SEARCH($F$2-1, $F15)), 1, 0) + IF(ISNUMBER(SEARCH($F$2-2, $F15)), 1, 0) + IF(ISNUMBER(SEARCH($F$2-3, $F15)), 1, 0) + IF(ISNUMBER(SEARCH($F$2-4, $F15)), 1, 0) + IF(ISNUMBER(SEARCH($F$2-5, $F15)), 1, 0) + IF(ISNUMBER(SEARCH($F$2-6, $F15)), 1, 0) + IF(ISNUMBER(SEARCH($F$2-7, $F15)), 1, 0) + IF(ISNUMBER(SEARCH($F$2-8, $F15)), 1, 0) + IF(ISNUMBER(SEARCH($F$2-9, $F15)), 1, 0) -> 0 | J15: =IF(F15="NA", "NA", IF(G15>0, 1, 0)) -> 0 | K15: =IF(F15="NA","NA",IF(H15>2,1,IF(H15>1,0.5,0))) -> 0 | L15: =IF(F15="NA","NA",IF(I15>5, 1, IF(I15>2, 0.5, 0))) -> 0 | M15: =SUMIF(J15:L15,"<>#N/A") -> 0 | N15: =IF(F15 = "NA", "NA", 0) -> 0 | O15: =IF(F15 = "NA", "NA", 0) -> 0 | P15: =IF(F15 = "NA", "NA", 0) -> 0 | Q15: =IF(F15 = "NA", "NA", 0) -> 0 | R15: =IF(F15 = "NA", "NA", 0) -> 0 | S15: =SUMIF(N15:R15,"<>#N/A") -> 0
A16: SO.HEW.LEB.000 | D16: Life Expectancy at Birth (1) | G16: =IF(LEN(TRIM(F16)) = 4, 1, IF(LEN(TRIM(F16)) > 5, LEN(TRIM(F16))-LEN(SUBSTITUTE(TRIM(F16),",",""))+1, 0)) -> 0 | H16: =IF(ISNUMBER(SEARCH($F$2, $F16)), 1, 0) + IF(ISNUMBER(SEARCH($F$2-1, $F16)), 1, 0) + IF(ISNUMBER(SEARCH($F$2-2, $F16)), 1, 0) + IF(ISNUMBER(SEARCH($F$2-3, $F16)), 1, 0) + IF(ISNUMBER(SEARCH($F$2-4, $F16)), 1, 0) -> 0 | I16: =IF(ISNUMBER(SEARCH($F$2, $F16)), 1, 0) + IF(ISNUMBER(SEARCH($F$2-1, $F16)), 1, 0) + IF(ISNUMBER(SEARCH($F$2-2, $F16)), 1, 0) + IF(ISNUMBER(SEARCH($F$2-3, $F16)), 1, 0) + IF(ISNUMBER(SEARCH($F$2-4, $F16)), 1, 0) + IF(ISNUMBER(SEARCH($F$2-5, $F16)), 1, 0) + IF(ISNUMBER(SEARCH($F$2-6, $F16)), 1, 0) + IF(ISNUMBER(SEARCH($F$2-7, $F16)), 1, 0) + IF(ISNUMBER(SEARCH($F$2-8, $F16)), 1, 0) + IF(ISNUMBER(SEARCH($F$2-9, $F16)), 1, 0) -> 0 | J16: =IF(F16="NA", "NA", IF(G16>0, 1, 0)) -> 0 | K16: =IF(F16="NA","NA",IF(H16>2,1,IF(H16>1,0.5,0))) -> 0 | L16: =IF(F16="NA","NA",IF(I16>5, 1, IF(I16>2, 0.5, 0))) -> 0 | M16: =SUMIF(J16:L16,"<>#N/A") -> 0 | N16: =IF(F16 = "NA", "NA", 0) -> 0 | O16: =IF(F16 = "NA", "NA", 0) -> 0 | P16: =IF(F16 = "NA", "NA", 0) -> 0 | Q16: =IF(F16 = "NA", "NA", 0) -> 0 | R16: =IF(F16 = "NA", "NA", 0) -> 0 | S16: =SUMIF(N16:R16,"<>#N/A") -> 0
A17: SO.HEW.MR1.000 | D17: Neonatal Mortality Rate Per 1,000 Live Births (1) | G17: =IF(LEN(TRIM(F17)) = 4, 1, IF(LEN(TRIM(F17)) > 5, LEN(TRIM(F17))-LEN(SUBSTITUTE(TRIM(F17),",",""))+1, 0)) -> 0 | H17: =IF(ISNUMBER(SEARCH($F$2, $F17)), 1, 0) + IF(ISNUMBER(SEARCH($F$2-1, $F17)), 1, 0) + IF(ISNUMBER(SEARCH($F$2-2, $F17)), 1, 0) + IF(ISNUMBER(SEARCH($F$2-3, $F17)), 1, 0) + IF(ISNUMBER(SEARCH($F$2-4, $F17)), 1, 0) -> 0 | I17: =IF(ISNUMBER(SEARCH($F$2, $F17)), 1, 0) + IF(ISNUMBER(SEARCH($F$2-1, $F17)), 1, 0) + IF(ISNUMBER(SEARCH($F$2-2, $F17)), 1, 0) + IF(ISNUMBER(SEARCH($F$2-3, $F17)), 1, 0) + IF(ISNUMBER(SEARCH($F$2-4, $F17)), 1, 0) + IF(ISNUMBER(SEARCH($F$2-5, $F17)), 1, 0) + IF(ISNUMBER(SEARCH($F$2-6, $F17)), 1, 0) + IF(ISNUMBER(SEARCH($F$2-7, $F17)), 1, 0) + IF(ISNUMBER(SEARCH($F$2-8, $F17)), 1, 0) + IF(ISNUMBER(SEARCH($F$2-9, $F17)), 1, 0) -> 0 | J17: =IF(F17="NA", "NA", IF(G17>0, 1, 0)) -> 0 | K17: =IF(F17="NA","NA",IF(H17>2,1,IF(H17>1,0.5,0))) -> 0 | L17: =IF(F17="NA","NA",IF(I17>5, 1, IF(I17>2, 0.5, 0))) -> 0 | M17: =SUMIF(J17:L17,"<>#N/A") -> 0 | N17: =IF(F17 = "NA", "NA", 0) -> 0 | O17: =IF(F17 = "NA", "NA", 0) -> 0 | P17: =IF(F17 = "NA", "NA", 0) -> 0 | Q17: =IF(F17 = "NA", "NA", 0) -> 0 | R17: =IF(F17 = "NA", "NA", 0) -> 0 | S17: =SUMIF(N17:R17,"<>#N/A") -> 0
A18: SO.HEW.MR5.000 | D18: Under-5 Mortality Rate Per 1,000 Live Births (1) | G18: =IF(LEN(TRIM(F18)) = 4, 1, IF(LEN(TRIM(F18)) > 5, LEN(TRIM(F18))-LEN(SUBSTITUTE(TRIM(F18),",",""))+1, 0)) -> 0 | H18: =IF(ISNUMBER(SEARCH($F$2, $F18)), 1, 0) + IF(ISNUMBER(SEARCH($F$2-1, $F18)), 1, 0) + IF(ISNUMBER(SEARCH($F$2-2, $F18)), 1, 0) + IF(ISNUMBER(SEARCH($F$2-3, $F18)), 1, 0) + IF(ISNUMBER(SEARCH($F$2-4, $F18)), 1, 0) -> 0 | I18: =IF(ISNUMBER(SEARCH($F$2, $F18)), 1, 0) + IF(ISNUMBER(SEARCH($F$2-1, $F18)), 1, 0) + IF(ISNUMBER(SEARCH($F$2-2, $F18)), 1, 0) + IF(ISNUMBER(SEARCH($F$2-3, $F18)), 1, 0) + IF(ISNUMBER(SEARCH($F$2-4, $F18)), 1, 0) + IF(ISNUMBER(SEARCH($F$2-5, $F18)), 1, 0) + IF(ISNUMBER(SEARCH($F$2-6, $F18)), 1, 0) + IF(ISNUMBER(SEARCH($F$2-7, $F18)), 1, 0) + IF(ISNUMBER(SEARCH($F$2-8, $F18)), 1, 0) + IF(ISNUMBER(SEARCH($F$2-9, $F18)), 1, 0) -> 0 | J18: =IF(F18="NA", "NA", IF(G18>0, 1, 0)) -> 0 | K18: =IF(F18="NA","NA",IF(H18>2,1,IF(H18>1,0.5,0))) -> 0 | L18: =IF(F18="NA","NA",IF(I18>5, 1, IF(I18>2, 0.5, 0))) -> 0 | M18: =SUMIF(J18:L18,"<>#N/A") -> 0 | N18: =IF(F18 = "NA", "NA", 0) -> 0 | O18: =IF(F18 = "NA", "NA", 0) -> 0 | P18: =IF(F18 = "NA", "NA", 0) -> 0 | Q18: =IF(F18 = "NA", "NA", 0) -> 0 | R18: =IF(F18 = "NA", "NA", 0) -> 0 | S18: =SUMIF(N18:R18,"<>#N/A") -> 0
A19: SO.HEW.MR0.000 | D19: Maternal Mortality Ratio Per 100,000 Live Births (1) | G19: =IF(LEN(TRIM(F19)) = 4, 1, IF(LEN(TRIM(F19)) > 5, LEN(TRIM(F19))-LEN(SUBSTITUTE(TRIM(F19),",",""))+1, 0)) -> 0 | H19: =IF(ISNUMBER(SEARCH($F$2, $F19)), 1, 0) + IF(ISNUMBER(SEARCH($F$2-1, $F19)), 1, 0) + IF(ISNUMBER(SEARCH($F$2-2, $F19)), 1, 0) + IF(ISNUMBER(SEARCH($F$2-3, $F19)), 1, 0) + IF(ISNUMBER(SEARCH($F$2-4, $F19)), 1, 0) -> 0 | I19: =IF(ISNUMBER(SEARCH($F$2, $F19)), 1, 0) + IF(ISNUMBER(SEARCH($F$2-1, $F19)), 1, 0) + IF(ISNUMBER(SEARCH($F$2-2, $F19)), 1, 0) + IF(ISNUMBER(SEARCH($F$2-3, $F19)), 1, 0) + IF(ISNUMBER(SEARCH($F$2-4, $F19)), 1, 0) + IF(ISNUMBER(SEARCH($F$2-5, $F19)), 1, 0) + IF(ISNUMBER(SEARCH($F$2-6, $F19)), 1, 0) + IF(ISNUMBER(SEARCH($F$2-7, $F19)), 1, 0) + IF(ISNUMBER(SEARCH($F$2-8, $F19)), 1, 0) + IF(ISNUMBER(SEARCH($F$2-9, $F19)), 1, 0) -> 0 | J19: =IF(F19="NA", "NA", IF(G19>0, 1, 0)) -> 0 | K19: =IF(F19="NA","NA",IF(H19>2,1,IF(H19>1,0.5,0))) -> 0 | L19: =IF(F19="NA","NA",IF(I19>5, 1, IF(I19>2, 0.5, 0))) -> 0 | M19: =SUMIF(J19:L19,"<>#N/A") -> 0 | N19: =IF(F19 = "NA", "NA", 0) -> 0 | O19: =IF(F19 = "NA", "NA", 0) -> 0 | P19: =IF(F19 = "NA", "NA", 0) -> 0 | Q19: =IF(F19 = "NA", "NA", 0) -> 0 | R19: =IF(F19 = "NA", "NA", 0) -> 0 | S19: =SUMIF(N19:R19,"<>#N/A") -> 0
A20: SO.HEO.STN.000 | C20: Health Outcomes | D20: Prevalence of Stunting and Malnutrition among Children Under 5 Years of Age (1) | G20: =IF(LEN(TRIM(F20)) = 4, 1, IF(LEN(TRIM(F20)) > 5, LEN(TRIM(F20))-LEN(SUBSTITUTE(TRIM(F20),",",""))+1, 0)) -> 0 | H20: =IF(ISNUMBER(SEARCH($F$2, $F20)), 1, 0) + IF(ISNUMBER(SEARCH($F$2-1, $F20)), 1, 0) + IF(ISNUMBER(SEARCH($F$2-2, $F20)), 1, 0) + IF(ISNUMBER(SEARCH($F$2-3, $F20)), 1, 0) + IF(ISNUMBER(SEARCH($F$2-4, $F20)), 1, 0) -> 0 | I20: =IF(ISNUMBER(SEARCH($F$2, $F20)), 1, 0) + IF(ISNUMBER(SEARCH($F$2-1, $F20)), 1, 0) + IF(ISNUMBER(SEARCH($F$2-2, $F20)), 1, 0) + IF(ISNUMBER(SEARCH($F$2-3, $F20)), 1, 0) + IF(ISNUMBER(SEARCH($F$2-4, $F20)), 1, 0) + IF(ISNUMBER(SEARCH($F$2-5, $F20)), 1, 0) + IF(ISNUMBER(SEARCH($F$2-6, $F20)), 1, 0) + IF(ISNUMBER(SEARCH($F$2-7, $F20)), 1, 0) + IF(ISNUMBER(SEARCH($F$2-8, $F20)), 1, 0) + IF(ISNUMBER(SEARCH($F$2-9, $F20)), 1, 0) -> 0 | J20: =IF(F20="NA", "NA", IF(G20>0, 1, 0)) -> 0 | K20: =IF(F20="NA","NA",IF(H20>2,1,IF(H20>1,0.5,0))) -> 0 | L20: =IF(F20="NA","NA",IF(I20>5, 1, IF(I20>2, 0.5, 0))) -> 0 | M20: =SUMIF(J20:L20,"<>#N/A") -> 0 | N20: =IF(F20 = "NA", "NA", 0) -> 0 | O20: =IF(F20 = "NA", "NA", 0) -> 0 | P20: =IF(F20 = "NA", "NA", 0) -> 0 | Q20: =IF(F20 = "NA", "NA", 0) -> 0 | R20: =IF(F20 = "NA", "NA", 0) -> 0 | S20: =SUMIF(N20:R20,"<>#N/A") -> 0
A21: SO.HEO.DIR.006 | D21: Disease Incidence Rate (3) | E21: i. Tuberculosis | G21: =IF(LEN(TRIM(F21)) = 4, 1, IF(LEN(TRIM(F21)) > 5, LEN(TRIM(F21))-LEN(SUBSTITUTE(TRIM(F21),",",""))+1, 0)) -> 0 | H21: =IF(ISNUMBER(SEARCH($F$2, $F21)), 1, 0) + IF(ISNUMBER(SEARCH($F$2-1, $F21)), 1, 0) + IF(ISNUMBER(SEARCH($F$2-2, $F21)), 1, 0) + IF(ISNUMBER(SEARCH($F$2-3, $F21)), 1, 0) + IF(ISNUMBER(SEARCH($F$2-4, $F21)), 1, 0) -> 0 | I21: =IF(ISNUMBER(SEARCH($F$2, $F21)), 1, 0) + IF(ISNUMBER(SEARCH($F$2-1, $F21)), 1, 0) + IF(ISNUMBER(SEARCH($F$2-2, $F21)), 1, 0) + IF(ISNUMBER(SEARCH($F$2-3, $F21)), 1, 0) + IF(ISNUMBER(SEARCH($F$2-4, $F21)), 1, 0) + IF(ISNUMBER(SEARCH($F$2-5, $F21)), 1, 0) + IF(ISNUMBER(SEARCH($F$2-6, $F21)), 1, 0) + IF(ISNUMBER(SEARCH($F$2-7, $F21)), 1, 0) + IF(ISNUMBER(SEARCH($F$2-8, $F21)), 1, 0) + IF(ISNUMBER(SEARCH($F$2-9, $F21)), 1, 0) -> 0 | J21: =IF(F21="NA", "NA", IF(G21>0, 1, 0)) -> 0 | K21: =IF(F21="NA","NA",IF(H21>2,1,IF(H21>1,0.5,0))) -> 0 | L21: =IF(F21="NA","NA",IF(I21>5, 1, IF(I21>2, 0.5, 0))) -> 0 | M21: =SUMIF(J21:L21,"<>#N/A") -> 0 | N21: =IF(F21 = "NA", "NA", 0) -> 0 | O21: =IF(F21 = "NA", "NA", 0) -> 0 | P21: =IF(F21 = "NA", "NA", 0) -> 0 | Q21: =IF(F21 = "NA", "NA", 0) -> 0 | R21: =IF(F21 = "NA", "NA", 0) -> 0 | S21: =SUMIF(N21:R21,"<>#N/A") -> 0
A22: SO.HEO.DIR.007 | E22: ii. Malaria | G22: =IF(LEN(TRIM(F22)) = 4, 1, IF(LEN(TRIM(F22)) > 5, LEN(TRIM(F22))-LEN(SUBSTITUTE(TRIM(F22),",",""))+1, 0)) -> 0 | H22: =IF(ISNUMBER(SEARCH($F$2, $F22)), 1, 0) + IF(ISNUMBER(SEARCH($F$2-1, $F22)), 1, 0) + IF(ISNUMBER(SEARCH($F$2-2, $F22)), 1, 0) + IF(ISNUMBER(SEARCH($F$2-3, $F22)), 1, 0) + IF(ISNUMBER(SEARCH($F$2-4, $F22)), 1, 0) -> 0 | I22: =IF(ISNUMBER(SEARCH($F$2, $F22)), 1, 0) + IF(ISNUMBER(SEARCH($F$2-1, $F22)), 1, 0) + IF(ISNUMBER(SEARCH($F$2-2, $F22)), 1, 0) + IF(ISNUMBER(SEARCH($F$2-3, $F22)), 1, 0) + IF(ISNUMBER(SEARCH($F$2-4, $F22)), 1, 0) + IF(ISNUMBER(SEARCH($F$2-5, $F22)), 1, 0) + IF(ISNUMBER(SEARCH($F$2-6, $F22)), 1, 0) + IF(ISNUMBER(SEARCH($F$2-7, $F22)), 1, 0) + IF(ISNUMBER(SEARCH($F$2-8, $F22)), 1, 0) + IF(ISNUMBER(SEARCH($F$2-9, $F22)), 1, 0) -> 0 | J22: =IF(F22="NA", "NA", IF(G22>0, 1, 0)) -> 0 | K22: =IF(F22="NA","NA",IF(H22>2,1,IF(H22>1,0.5,0))) -> 0 | L22: =IF(F22="NA","NA",IF(I22>5, 1, IF(I22>2, 0.5, 0))) -> 0 | M22: =SUMIF(J22:L22,"<>#N/A") -> 0 | N22: =IF(F22 = "NA", "NA", 0) -> 0 | O22: =IF(F22 = "NA", "NA", 0) -> 0 | P22: =IF(F22 = "NA", "NA", 0) -> 0 | Q22: =IF(F22 = "NA", "NA", 0) -> 0 | R22: =IF(F22 = "NA", "NA", 0) -> 0 | S22: =SUMIF(N22:R22,"<>#N/A") -> 0
A23: SO.HEO.DIR.008 | E23: iii. HIV | G23: =IF(LEN(TRIM(F23)) = 4, 1, IF(LEN(TRIM(F23)) > 5, LEN(TRIM(F23))-LEN(SUBSTITUTE(TRIM(F23),",",""))+1, 0)) -> 0 | H23: =IF(ISNUMBER(SEARCH($F$2, $F23)), 1, 0) + IF(ISNUMBER(SEARCH($F$2-1, $F23)), 1, 0) + IF(ISNUMBER(SEARCH($F$2-2, $F23)), 1, 0) + IF(ISNUMBER(SEARCH($F$2-3, $F23)), 1, 0) + IF(ISNUMBER(SEARCH($F$2-4, $F23)), 1, 0) -> 0 | I23: =IF(ISNUMBER(SEARCH($F$2, $F23)), 1, 0) + IF(ISNUMBER(SEARCH($F$2-1, $F23)), 1, 0) + IF(ISNUMBER(SEARCH($F$2-2, $F23)), 1, 0) + IF(ISNUMBER(SEARCH($F$2-3, $F23)), 1, 0) + IF(ISNUMBER(SEARCH($F$2-4, $F23)), 1, 0) + IF(ISNUMBER(SEARCH($F$2-5, $F23)), 1, 0) + IF(ISNUMBER(SEARCH($F$2-6, $F23)), 1, 0) + IF(ISNUMBER(SEARCH($F$2-7, $F23)), 1, 0) + IF(ISNUMBER(SEARCH($F$2-8, $F23)), 1, 0) + IF(ISNUMBER(SEARCH($F$2-9, $F23)), 1, 0) -> 0 | J23: =IF(F23="NA", "NA", IF(G23>0, 1, 0)) -> 0 | K23: =IF(F23="NA","NA",IF(H23>2,1,IF(H23>1,0.5,0))) -> 0 | L23: =IF(F23="NA","NA",IF(I23>5, 1, IF(I23>2, 0.5, 0))) -> 0 | M23: =SUMIF(J23:L23,"<>#N/A") -> 0 | N23: =IF(F23 = "NA", "NA", 0) -> 0 | O23: =IF(F23 = "NA", "NA", 0) -> 0 | P23: =IF(F23 = "NA", "NA", 0) -> 0 | Q23: =IF(F23 = "NA", "NA", 0) -> 0 | R23: =IF(F23 = "NA", "NA", 0) -> 0 | S23: =SUMIF(N23:R23,"<>#N/A") -> 0
A24: SO.EDU.ENR.001 | C24: Education | D24: Enrolment Ratio (Gross/ Net) (3) | E24: i. Total | G24: =IF(LEN(TRIM(F24)) = 4, 1, IF(LEN(TRIM(F24)) > 5, LEN(TRIM(F24))-LEN(SUBSTITUTE(TRIM(F24),",",""))+1, 0)) -> 0 | H24: =IF(ISNUMBER(SEARCH($F$2, $F24)), 1, 0) + IF(ISNUMBER(SEARCH($F$2-1, $F24)), 1, 0) + IF(ISNUMBER(SEARCH($F$2-2, $F24)), 1, 0) + IF(ISNUMBER(SEARCH($F$2-3, $F24)), 1, 0) + IF(ISNUMBER(SEARCH($F$2-4, $F24)), 1, 0) -> 0 | I24: =IF(ISNUMBER(SEARCH($F$2, $F24)), 1, 0) + IF(ISNUMBER(SEARCH($F$2-1, $F24)), 1, 0) + IF(ISNUMBER(SEARCH($F$2-2, $F24)), 1, 0) + IF(ISNUMBER(SEARCH($F$2-3, $F24)), 1, 0) + IF(ISNUMBER(SEARCH($F$2-4, $F24)), 1, 0) + IF(ISNUMBER(SEARCH($F$2-5, $F24)), 1, 0) + IF(ISNUMBER(SEARCH($F$2-6, $F24)), 1, 0) + IF(ISNUMBER(SEARCH($F$2-7, $F24)), 1, 0) + IF(ISNUMBER(SEARCH($F$2-8, $F24)), 1, 0) + IF(ISNUMBER(SEARCH($F$2-9, $F24)), 1, 0) -> 0 | J24: =IF(F24="NA", "NA", IF(G24>0, 1, 0)) -> 0 | K24: =IF(F24="NA","NA",IF(H24>2,1,IF(H24>1,0.5,0))) -> 0 | L24: =IF(F24="NA","NA",IF(I24>5, 1, IF(I24>2, 0.5, 0))) -> 0 | M24: =SUMIF(J24:L24,"<>#N/A") -> 0 | N24: =IF(F24 = "NA", "NA", 0) -> 0 | O24: =IF(F24 = "NA", "NA", 0) -> 0 | P24: =IF(F24 = "NA", "NA", 0) -> 0 | Q24: =IF(F24 = "NA", "NA", 0) -> 0 | R24: =IF(F24 = "NA", "NA", 0) -> 0 | S24: =SUMIF(N24:R24,"<>#N/A") -> 0
A25: SO.EDU.ENR.002 | E25: ii. By Sex | G25: =IF(LEN(TRIM(F25)) = 4, 1, IF(LEN(TRIM(F25)) > 5, LEN(TRIM(F25))-LEN(SUBSTITUTE(TRIM(F25),",",""))+1, 0)) -> 0 | H25: =IF(ISNUMBER(SEARCH($F$2, $F25)), 1, 0) + IF(ISNUMBER(SEARCH($F$2-1, $F25)), 1, 0) + IF(ISNUMBER(SEARCH($F$2-2, $F25)), 1, 0) + IF(ISNUMBER(SEARCH($F$2-3, $F25)), 1, 0) + IF(ISNUMBER(SEARCH($F$2-4, $F25)), 1, 0) -> 0 | I25: =IF(ISNUMBER(SEARCH($F$2, $F25)), 1, 0) + IF(ISNUMBER(SEARCH($F$2-1, $F25)), 1, 0) + IF(ISNUMBER(SEARCH($F$2-2, $F25)), 1, 0) + IF(ISNUMBER(SEARCH($F$2-3, $F25)), 1, 0) + IF(ISNUMBER(SEARCH($F$2-4, $F25)), 1, 0) + IF(ISNUMBER(SEARCH($F$2-5, $F25)), 1, 0) + IF(ISNUMBER(SEARCH($F$2-6, $F25)), 1, 0) + IF(ISNUMBER(SEARCH($F$2-7, $F25)), 1, 0) + IF(ISNUMBER(SEARCH($F$2-8, $F25)), 1, 0) + IF(ISNUMBER(SEARCH($F$2-9, $F25)), 1, 0) -> 0 | J25: =IF(F25="NA", "NA", IF(G25>0, 1, 0)) -> 0 | K25: =IF(F25="NA","NA",IF(H25>2,1,IF(H25>1,0.5,0))) -> 0 | L25: =IF(F25="NA","NA",IF(I25>5, 1, IF(I25>2, 0.5, 0))) -> 0 | M25: =SUMIF(J25:L25,"<>#N/A") -> 0 | N25: =IF(F25 = "NA", "NA", 0) -> 0 | O25: =IF(F25 = "NA", "NA", 0) -> 0 | P25: =IF(F25 = "NA", "NA", 0) -> 0 | Q25: =IF(F25 = "NA", "NA", 0) -> 0 | R25: =IF(F25 = "NA", "NA", 0) -> 0 | S25: =SUMIF(N25:R25,"<>#N/A") -> 0
A26: SO.EDU.ENR.009 | E26: iii. By Level (Primary, Secondary and Tertiary) | G26: =IF(LEN(TRIM(F26)) = 4, 1, IF(LEN(TRIM(F26)) > 5, LEN(TRIM(F26))-LEN(SUBSTITUTE(TRIM(F26),",",""))+1, 0)) -> 0 | H26: =IF(ISNUMBER(SEARCH($F$2, $F26)), 1, 0) + IF(ISNUMBER(SEARCH($F$2-1, $F26)), 1, 0) + IF(ISNUMBER(SEARCH($F$2-2, $F26)), 1, 0) + IF(ISNUMBER(SEARCH($F$2-3, $F26)), 1, 0) + IF(ISNUMBER(SEARCH($F$2-4, $F26)), 1, 0) -> 0 | I26: =IF(ISNUMBER(SEARCH($F$2, $F26)), 1, 0) + IF(ISNUMBER(SEARCH($F$2-1, $F26)), 1, 0) + IF(ISNUMBER(SEARCH($F$2-2, $F26)), 1, 0) + IF(ISNUMBER(SEARCH($F$2-3, $F26)), 1, 0) + IF(ISNUMBER(SEARCH($F$2-4, $F26)), 1, 0) + IF(ISNUMBER(SEARCH($F$2-5, $F26)), 1, 0) + IF(ISNUMBER(SEARCH($F$2-6, $F26)), 1, 0) + IF(ISNUMBER(SEARCH($F$2-7, $F26)), 1, 0) + IF(ISNUMBER(SEARCH($F$2-8, $F26)), 1, 0) + IF(ISNUMBER(SEARCH($F$2-9, $F26)), 1, 0) -> 0 | J26: =IF(F26="NA", "NA", IF(G26>0, 1, 0)) -> 0 | K26: =IF(F26="NA","NA",IF(H26>2,1,IF(H26>1,0.5,0))) -> 0 | L26: =IF(F26="NA","NA",IF(I26>5, 1, IF(I26>2, 0.5, 0))) -> 0 | M26: =SUMIF(J26:L26,"<>#N/A") -> 0 | N26: =IF(F26 = "NA", "NA", 0) -> 0 | O26: =IF(F26 = "NA", "NA", 0) -> 0 | P26: =IF(F26 = "NA", "NA", 0) -> 0 | Q26: =IF(F26 = "NA", "NA", 0) -> 0 | R26: =IF(F26 = "NA", "NA", 0) -> 0 | S26: =SUMIF(N26:R26,"<>#N/A") -> 0
A27: SO.EDU.ALR.001 | D27: Adult Literacy Rate (2) | E27: i. Total | G27: =IF(LEN(TRIM(F27)) = 4, 1, IF(LEN(TRIM(F27)) > 5, LEN(TRIM(F27))-LEN(SUBSTITUTE(TRIM(F27),",",""))+1, 0)) -> 0 | H27: =IF(ISNUMBER(SEARCH($F$2, $F27)), 1, 0) + IF(ISNUMBER(SEARCH($F$2-1, $F27)), 1, 0) + IF(ISNUMBER(SEARCH($F$2-2, $F27)), 1, 0) + IF(ISNUMBER(SEARCH($F$2-3, $F27)), 1, 0) + IF(ISNUMBER(SEARCH($F$2-4, $F27)), 1, 0) -> 0 | I27: =IF(ISNUMBER(SEARCH($F$2, $F27)), 1, 0) + IF(ISNUMBER(SEARCH($F$2-1, $F27)), 1, 0) + IF(ISNUMBER(SEARCH($F$2-2, $F27)), 1, 0) + IF(ISNUMBER(SEARCH($F$2-3, $F27)), 1, 0) + IF(ISNUMBER(SEARCH($F$2-4, $F27)), 1, 0) + IF(ISNUMBER(SEARCH($F$2-5, $F27)), 1, 0) + IF(ISNUMBER(SEARCH($F$2-6, $F27)), 1, 0) + IF(ISNUMBER(SEARCH($F$2-7, $F27)), 1, 0) + IF(ISNUMBER(SEARCH($F$2-8, $F27)), 1, 0) + IF(ISNUMBER(SEARCH($F$2-9, $F27)), 1, 0) -> 0 | J27: =IF(F27="NA", "NA", IF(G27>0, 1, 0)) -> 0 | K27: =IF(F27="NA","NA",IF(H27>2,1,IF(H27>1,0.5,0))) -> 0 | L27: =IF(F27="NA","NA",IF(I27>5, 1, IF(I27>2, 0.5, 0))) -> 0 | M27: =SUMIF(J27:L27,"<>#N/A") -> 0 | N27: =IF(F27 = "NA", "NA", 0) -> 0 | O27: =IF(F27 = "NA", "NA", 0) -> 0 | P27: =IF(F27 = "NA", "NA", 0) -> 0 | Q27: =IF(F27 = "NA", "NA", 0) -> 0 | R27: =IF(F27 = "NA", "NA", 0) -> 0 | S27: =SUMIF(N27:R27,"<>#N/A") -> 0
A28: SO.EDU.ALR.002 | E28: ii. By Sex | G28: =IF(LEN(TRIM(F28)) = 4, 1, IF(LEN(TRIM(F28)) > 5, LEN(TRIM(F28))-LEN(SUBSTITUTE(TRIM(F28),",",""))+1, 0)) -> 0 | H28: =IF(ISNUMBER(SEARCH($F$2, $F28)), 1, 0) + IF(ISNUMBER(SEARCH($F$2-1, $F28)), 1, 0) + IF(ISNUMBER(SEARCH($F$2-2, $F28)), 1, 0) + IF(ISNUMBER(SEARCH($F$2-3, $F28)), 1, 0) + IF(ISNUMBER(SEARCH($F$2-4, $F28)), 1, 0) -> 0 | I28: =IF(ISNUMBER(SEARCH($F$2, $F28)), 1, 0) + IF(ISNUMBER(SEARCH($F$2-1, $F28)), 1, 0) + IF(ISNUMBER(SEARCH($F$2-2, $F28)), 1, 0) + IF(ISNUMBER(SEARCH($F$2-3, $F28)), 1, 0) + IF(ISNUMBER(SEARCH($F$2-4, $F28)), 1, 0) + IF(ISNUMBER(SEARCH($F$2-5, $F28)), 1, 0) + IF(ISNUMBER(SEARCH($F$2-6, $F28)), 1, 0) + IF(ISNUMBER(SEARCH($F$2-7, $F28)), 1, 0) + IF(ISNUMBER(SEARCH($F$2-8, $F28)), 1, 0) + IF(ISNUMBER(SEARCH($F$2-9, $F28)), 1, 0) -> 0 | J28: =IF(F28="NA", "NA", IF(G28>0, 1, 0)) -> 0 | K28: =IF(F28="NA","NA",IF(H28>2,1,IF(H28>1,0.5,0))) -> 0 | L28: =IF(F28="NA","NA",IF(I28>5, 1, IF(I28>2, 0.5, 0))) -> 0 | M28: =SUMIF(J28:L28,"<>#N/A") -> 0 | N28: =IF(F28 = "NA", "NA", 0) -> 0 | O28: =IF(F28 = "NA", "NA", 0) -> 0 | P28: =IF(F28 = "NA", "NA", 0) -> 0 | Q28: =IF(F28 = "NA", "NA", 0) -> 0 | R28: =IF(F28 = "NA", "NA", 0) -> 0 | S28: =SUMIF(N28:R28,"<>#N/A") -> 0
A29: SO.LAB.UIR.001 | C29: Labour | D29: Unemployment Rate (3) | E29: i. Total | G29: =IF(LEN(TRIM(F29)) = 4, 1, IF(LEN(TRIM(F29)) > 5, LEN(TRIM(F29))-LEN(SUBSTITUTE(TRIM(F29),",",""))+1, 0)) -> 0 | H29: =IF(ISNUMBER(SEARCH($F$2, $F29)), 1, 0) + IF(ISNUMBER(SEARCH($F$2-1, $F29)), 1, 0) + IF(ISNUMBER(SEARCH($F$2-2, $F29)), 1, 0) + IF(ISNUMBER(SEARCH($F$2-3, $F29)), 1, 0) + IF(ISNUMBER(SEARCH($F$2-4, $F29)), 1, 0) -> 0 | I29: =IF(ISNUMBER(SEARCH($F$2, $F29)), 1, 0) + IF(ISNUMBER(SEARCH($F$2-1, $F29)), 1, 0) + IF(ISNUMBER(SEARCH($F$2-2, $F29)), 1, 0) + IF(ISNUMBER(SEARCH($F$2-3, $F29)), 1, 0) + IF(ISNUMBER(SEARCH($F$2-4, $F29)), 1, 0) + IF(ISNUMBER(SEARCH($F$2-5, $F29)), 1, 0) + IF(ISNUMBER(SEARCH($F$2-6, $F29)), 1, 0) + IF(ISNUMBER(SEARCH($F$2-7, $F29)), 1, 0) + IF(ISNUMBER(SEARCH($F$2-8, $F29)), 1, 0) + IF(ISNUMBER(SEARCH($F$2-9, $F29)), 1, 0) -> 0 | J29: =IF(F29="NA", "NA", IF(G29>0, 1, 0)) -> 0 | K29: =IF(F29="NA","NA",IF(H29>2,1,IF(H29>1,0.5,0))) -> 0 | L29: =IF(F29="NA","NA",IF(I29>5, 1, IF(I29>2, 0.5, 0))) -> 0 | M29: =SUMIF(J29:L29,"<>#N/A") -> 0 | N29: =IF(F29 = "NA", "NA", 0) -> 0 | O29: =IF(F29 = "NA", "NA", 0) -> 0 | P29: =IF(F29 = "NA", "NA", 0) -> 0 | Q29: =IF(F29 = "NA", "NA", 0) -> 0 | R29: =IF(F29 = "NA", "NA", 0) -> 0 | S29: =SUMIF(N29:R29,"<>#N/A") -> 0
A30: SO.LAB.UIR.002 | E30: ii. By Sex | G30: =IF(LEN(TRIM(F30)) = 4, 1, IF(LEN(TRIM(F30)) > 5, LEN(TRIM(F30))-LEN(SUBSTITUTE(TRIM(F30),",",""))+1, 0)) -> 0 | H30: =IF(ISNUMBER(SEARCH($F$2, $F30)), 1, 0) + IF(ISNUMBER(SEARCH($F$2-1, $F30)), 1, 0) + IF(ISNUMBER(SEARCH($F$2-2, $F30)), 1, 0) + IF(ISNUMBER(SEARCH($F$2-3, $F30)), 1, 0) + IF(ISNUMBER(SEARCH($F$2-4, $F30)), 1, 0) -> 0 | I30: =IF(ISNUMBER(SEARCH($F$2, $F30)), 1, 0) + IF(ISNUMBER(SEARCH($F$2-1, $F30)), 1, 0) + IF(ISNUMBER(SEARCH($F$2-2, $F30)), 1, 0) + IF(ISNUMBER(SEARCH($F$2-3, $F30)), 1, 0) + IF(ISNUMBER(SEARCH($F$2-4, $F30)), 1, 0) + IF(ISNUMBER(SEARCH($F$2-5, $F30)), 1, 0) + IF(ISNUMBER(SEARCH($F$2-6, $F30)), 1, 0) + IF(ISNUMBER(SEARCH($F$2-7, $F30)), 1, 0) + IF(ISNUMBER(SEARCH($F$2-8, $F30)), 1, 0) + IF(ISNUMBER(SEARCH($F$2-9, $F30)), 1, 0) -> 0 | J30: =IF(F30="NA", "NA", IF(G30>0, 1, 0)) -> 0 | K30: =IF(F30="NA","NA",IF(H30>2,1,IF(H30>1,0.5,0))) -> 0 | L30: =IF(F30="NA","NA",IF(I30>5, 1, IF(I30>2, 0.5, 0))) -> 0 | M30: =SUMIF(J30:L30,"<>#N/A") -> 0 | N30: =IF(F30 = "NA", "NA", 0) -> 0 | O30: =IF(F30 = "NA", "NA", 0) -> 0 | P30: =IF(F30 = "NA", "NA", 0) -> 0 | Q30: =IF(F30 = "NA", "NA", 0) -> 0 | R30: =IF(F30 = "NA", "NA", 0) -> 0 | S30: =SUMIF(N30:R30,"<>#N/A") -> 0
A31: SO.LAB.UIR.010 | E31: iii. By Age | G31: =IF(LEN(TRIM(F31)) = 4, 1, IF(LEN(TRIM(F31)) > 5, LEN(TRIM(F31))-LEN(SUBSTITUTE(TRIM(F31),",",""))+1, 0)) -> 0 | H31: =IF(ISNUMBER(SEARCH($F$2, $F31)), 1, 0) + IF(ISNUMBER(SEARCH($F$2-1, $F31)), 1, 0) + IF(ISNUMBER(SEARCH($F$2-2, $F31)), 1, 0) + IF(ISNUMBER(SEARCH($F$2-3, $F31)), 1, 0) + IF(ISNUMBER(SEARCH($F$2-4, $F31)), 1, 0) -> 0 | I31: =IF(ISNUMBER(SEARCH($F$2, $F31)), 1, 0) + IF(ISNUMBER(SEARCH($F$2-1, $F31)), 1, 0) + IF(ISNUMBER(SEARCH($F$2-2, $F31)), 1, 0) + IF(ISNUMBER(SEARCH($F$2-3, $F31)), 1, 0) + IF(ISNUMBER(SEARCH($F$2-4, $F31)), 1, 0) + IF(ISNUMBER(SEARCH($F$2-5, $F31)), 1, 0) + IF(ISNUMBER(SEARCH($F$2-6, $F31)), 1, 0) + IF(ISNUMBER(SEARCH($F$2-7, $F31)), 1, 0) + IF(ISNUMBER(SEARCH($F$2-8, $F31)), 1, 0) + IF(ISNUMBER(SEARCH($F$2-9, $F31)), 1, 0) -> 0 | J31: =IF(F31="NA", "NA", IF(G31>0, 1, 0)) -> 0 | K31: =IF(F31="NA","NA",IF(H31>2,1,IF(H31>1,0.5,0))) -> 0 | L31: =IF(F31="NA","NA",IF(I31>5, 1, IF(I31>2, 0.5, 0))) -> 0 | M31: =SUMIF(J31:L31,"<>#N/A") -> 0 | N31: =IF(F31 = "NA", "NA", 0) -> 0 | O31: =IF(F31 = "NA", "NA", 0) -> 0 | P31: =IF(F31 = "NA", "NA", 0) -> 0 | Q31: =IF(F31 = "NA", "NA", 0) -> 0 | R31: =IF(F31 = "NA", "NA", 0) -> 0 | S31: =SUMIF(N31:R31,"<>#N/A") -> 0
A32: SO.LAB.PSW.001 | D32: Labour Force Participation Rate (3) | E32: i. Total | G32: =IF(LEN(TRIM(F32)) = 4, 1, IF(LEN(TRIM(F32)) > 5, LEN(TRIM(F32))-LEN(SUBSTITUTE(TRIM(F32),",",""))+1, 0)) -> 0 | H32: =IF(ISNUMBER(SEARCH($F$2, $F32)), 1, 0) + IF(ISNUMBER(SEARCH($F$2-1, $F32)), 1, 0) + IF(ISNUMBER(SEARCH($F$2-2, $F32)), 1, 0) + IF(ISNUMBER(SEARCH($F$2-3, $F32)), 1, 0) + IF(ISNUMBER(SEARCH($F$2-4, $F32)), 1, 0) -> 0 | I32: =IF(ISNUMBER(SEARCH($F$2, $F32)), 1, 0) + IF(ISNUMBER(SEARCH($F$2-1, $F32)), 1, 0) + IF(ISNUMBER(SEARCH($F$2-2, $F32)), 1, 0) + IF(ISNUMBER(SEARCH($F$2-3, $F32)), 1, 0) + IF(ISNUMBER(SEARCH($F$2-4, $F32)), 1, 0) + IF(ISNUMBER(SEARCH($F$2-5, $F32)), 1, 0) + IF(ISNUMBER(SEARCH($F$2-6, $F32)), 1, 0) + IF(ISNUMBER(SEARCH($F$2-7, $F32)), 1, 0) + IF(ISNUMBER(SEARCH($F$2-8, $F32)), 1, 0) + IF(ISNUMBER(SEARCH($F$2-9, $F32)), 1, 0) -> 0 | J32: =IF(F32="NA", "NA", IF(G32>0, 1, 0)) -> 0 | K32: =IF(F32="NA","NA",IF(H32>2,1,IF(H32>1,0.5,0))) -> 0 | L32: =IF(F32="NA","NA",IF(I32>5, 1, IF(I32>2, 0.5, 0))) -> 0 | M32: =SUMIF(J32:L32,"<>#N/A") -> 0 | N32: =IF(F32 = "NA", "NA", 0) -> 0 | O32: =IF(F32 = "NA", "NA", 0) -> 0 | P32: =IF(F32 = "NA", "NA", 0) -> 0 | Q32: =IF(F32 = "NA", "NA", 0) -> 0 | R32: =IF(F32 = "NA", "NA", 0) -> 0 | S32: =SUMIF(N32:R32,"<>#N/A") -> 0
A33: SO.LAB.PSW.002 | E33: ii. By Sex | G33: =IF(LEN(TRIM(F33)) = 4, 1, IF(LEN(TRIM(F33)) > 5, LEN(TRIM(F33))-LEN(SUBSTITUTE(TRIM(F33),",",""))+1, 0)) -> 0 | H33: =IF(ISNUMBER(SEARCH($F$2, $F33)), 1, 0) + IF(ISNUMBER(SEARCH($F$2-1, $F33)), 1, 0) + IF(ISNUMBER(SEARCH($F$2-2, $F33)), 1, 0) + IF(ISNUMBER(SEARCH($F$2-3, $F33)), 1, 0) + IF(ISNUMBER(SEARCH($F$2-4, $F33)), 1, 0) -> 0 | I33: =IF(ISNUMBER(SEARCH($F$2, $F33)), 1, 0) + IF(ISNUMBER(SEARCH($F$2-1, $F33)), 1, 0) + IF(ISNUMBER(SEARCH($F$2-2, $F33)), 1, 0) + IF(ISNUMBER(SEARCH($F$2-3, $F33)), 1, 0) + IF(ISNUMBER(SEARCH($F$2-4, $F33)), 1, 0) + IF(ISNUMBER(SEARCH($F$2-5, $F33)), 1, 0) + IF(ISNUMBER(SEARCH($F$2-6, $F33)), 1, 0) + IF(ISNUMBER(SEARCH($F$2-7, $F33)), 1, 0) + IF(ISNUMBER(SEARCH($F$2-8, $F33)), 1, 0) + IF(ISNUMBER(SEARCH($F$2-9, $F33)), 1, 0) -> 0 | J33: =IF(F33="NA", "NA", IF(G33>0, 1, 0)) -> 0 | K33: =IF(F33="NA","NA",IF(H33>2,1,IF(H33>1,0.5,0))) -> 0 | L33: =IF(F33="NA","NA",IF(I33>5, 1, IF(I33>2, 0.5, 0))) -> 0 | M33: =SUMIF(J33:L33,"<>#N/A") -> 0 | N33: =IF(F33 = "NA", "NA", 0) -> 0 | O33: =IF(F33 = "NA", "NA", 0) -> 0 | P33: =IF(F33 = "NA", "NA", 0) -> 0 | Q33: =IF(F33 = "NA", "NA", 0) -> 0 | R33: =IF(F33 = "NA", "NA", 0) -> 0 | S33: =SUMIF(N33:R33,"<>#N/A") -> 0
A34: SO.LAB.PSW.004 | E34: iii. By Age Group | G34: =IF(LEN(TRIM(F34)) = 4, 1, IF(LEN(TRIM(F34)) > 5, LEN(TRIM(F34))-LEN(SUBSTITUTE(TRIM(F34),",",""))+1, 0)) -> 0 | H34: =IF(ISNUMBER(SEARCH($F$2, $F34)), 1, 0) + IF(ISNUMBER(SEARCH($F$2-1, $F34)), 1, 0) + IF(ISNUMBER(SEARCH($F$2-2, $F34)), 1, 0) + IF(ISNUMBER(SEARCH($F$2-3, $F34)), 1, 0) + IF(ISNUMBER(SEARCH($F$2-4, $F34)), 1, 0) -> 0 | I34: =IF(ISNUMBER(SEARCH($F$2, $F34)), 1, 0) + IF(ISNUMBER(SEARCH($F$2-1, $F34)), 1, 0) + IF(ISNUMBER(SEARCH($F$2-2, $F34)), 1, 0) + IF(ISNUMBER(SEARCH($F$2-3, $F34)), 1, 0) + IF(ISNUMBER(SEARCH($F$2-4, $F34)), 1, 0) + IF(ISNUMBER(SEARCH($F$2-5, $F34)), 1, 0) + IF(ISNUMBER(SEARCH($F$2-6, $F34)), 1, 0) + IF(ISNUMBER(SEARCH($F$2-7, $F34)), 1, 0) + IF(ISNUMBER(SEARCH($F$2-8, $F34)), 1, 0) + IF(ISNUMBER(SEARCH($F$2-9, $F34)), 1, 0) -> 0 | J34: =IF(F34="NA", "NA", IF(G34>0, 1, 0)) -> 0 | K34: =IF(F34="NA","NA",IF(H34>2,1,IF(H34>1,0.5,0))) -> 0 | L34: =IF(F34="NA","NA",IF(I34>5, 1, IF(I34>2, 0.5, 0))) -> 0 | M34: =SUMIF(J34:L34,"<>#N/A") -> 0 | N34: =IF(F34 = "NA", "NA", 0) -> 0 | O34: =IF(F34 = "NA", "NA", 0) -> 0 | P34: =IF(F34 = "NA", "NA", 0) -> 0 | Q34: =IF(F34 = "NA", "NA", 0) -> 0 | R34: =IF(F34 = "NA", "NA", 0) -> 0 | S34: =SUMIF(N34:R34,"<>#N/A") -> 0
A35: SO.GEE.GCP.011 | C35: Gender Equality | D35: Proportion of Seats Held by Women (2) | E35: i. Government/ Parliament | G35: =IF(LEN(TRIM(F35)) = 4, 1, IF(LEN(TRIM(F35)) > 5, LEN(TRIM(F35))-LEN(SUBSTITUTE(TRIM(F35),",",""))+1, 0)) -> 0 | H35: =IF(ISNUMBER(SEARCH($F$2, $F35)), 1, 0) + IF(ISNUMBER(SEARCH($F$2-1, $F35)), 1, 0) + IF(ISNUMBER(SEARCH($F$2-2, $F35)), 1, 0) + IF(ISNUMBER(SEARCH($F$2-3, $F35)), 1, 0) + IF(ISNUMBER(SEARCH($F$2-4, $F35)), 1, 0) -> 0 | I35: =IF(ISNUMBER(SEARCH($F$2, $F35)), 1, 0) + IF(ISNUMBER(SEARCH($F$2-1, $F35)), 1, 0) + IF(ISNUMBER(SEARCH($F$2-2, $F35)), 1, 0) + IF(ISNUMBER(SEARCH($F$2-3, $F35)), 1, 0) + IF(ISNUMBER(SEARCH($F$2-4, $F35)), 1, 0) + IF(ISNUMBER(SEARCH($F$2-5, $F35)), 1, 0) + IF(ISNUMBER(SEARCH($F$2-6, $F35)), 1, 0) + IF(ISNUMBER(SEARCH($F$2-7, $F35)), 1, 0) + IF(ISNUMBER(SEARCH($F$2-8, $F35)), 1, 0) + IF(ISNUMBER(SEARCH($F$2-9, $F35)), 1, 0) -> 0 | J35: =IF(F35="NA", "NA", IF(G35>0, 1, 0)) -> 0 | K35: =IF(F35="NA","NA",IF(H35>2,1,IF(H35>1,0.5,0))) -> 0 | L35: =IF(F35="NA","NA",IF(I35>5, 1, IF(I35>2, 0.5, 0))) -> 0 | M35: =SUMIF(J35:L35,"<>#N/A") -> 0 | N35: =IF(F35 = "NA", "NA", 0) -> 0 | O35: =IF(F35 = "NA", "NA", 0) -> 0 | P35: =IF(F35 = "NA", "NA", 0) -> 0 | Q35: =IF(F35 = "NA", "NA", 0) -> 0 | R35: =IF(F35 = "NA", "NA", 0) -> 0 | S35: =SUMIF(N35:R35,"<>#N/A") -> 0
A36: SO.GEE.GCP.012 | E36: ii. Management Positions | G36: =IF(LEN(TRIM(F36)) = 4, 1, IF(LEN(TRIM(F36)) > 5, LEN(TRIM(F36))-LEN(SUBSTITUTE(TRIM(F36),",",""))+1, 0)) -> 0 | H36: =IF(ISNUMBER(SEARCH($F$2, $F36)), 1, 0) + IF(ISNUMBER(SEARCH($F$2-1, $F36)), 1, 0) + IF(ISNUMBER(SEARCH($F$2-2, $F36)), 1, 0) + IF(ISNUMBER(SEARCH($F$2-3, $F36)), 1, 0) + IF(ISNUMBER(SEARCH($F$2-4, $F36)), 1, 0) -> 0 | I36: =IF(ISNUMBER(SEARCH($F$2, $F36)), 1, 0) + IF(ISNUMBER(SEARCH($F$2-1, $F36)), 1, 0) + IF(ISNUMBER(SEARCH($F$2-2, $F36)), 1, 0) + IF(ISNUMBER(SEARCH($F$2-3, $F36)), 1, 0) + IF(ISNUMBER(SEARCH($F$2-4, $F36)), 1, 0) + IF(ISNUMBER(SEARCH($F$2-5, $F36)), 1, 0) + IF(ISNUMBER(SEARCH($F$2-6, $F36)), 1, 0) + IF(ISNUMBER(SEARCH($F$2-7, $F36)), 1, 0) + IF(ISNUMBER(SEARCH($F$2-8, $F36)), 1, 0) + IF(ISNUMBER(SEARCH($F$2-9, $F36)), 1, 0) -> 0 | J36: =IF(F36="NA", "NA", IF(G36>0, 1, 0)) -> 0 | K36: =IF(F36="NA","NA",IF(H36>2,1,IF(H36>1,0.5,0))) -> 0 | L36: =IF(F36="NA","NA",IF(I36>5, 1, IF(I36>2, 0.5, 0))) -> 0 | M36: =SUMIF(J36:L36,"<>#N/A") -> 0 | N36: =IF(F36 = "NA", "NA", 0) -> 0 | O36: =IF(F36 = "NA", "NA", 0) -> 0 | P36: =IF(F36 = "NA", "NA", 0) -> 0 | Q36: =IF(F36 = "NA", "NA", 0) -> 0 | R36: =IF(F36 = "NA", "NA", 0) -> 0 | S36: =SUMIF(N36:R36,"<>#N/A") -> 0
A37: MA.GDP.FFR.001 | B37: Macroeconomic Indicators | C37: GDP | D37: GDP at Current Prices (2) | E37: i. Total | G37: =IF(LEN(TRIM(F37)) = 4, 1, IF(LEN(TRIM(F37)) > 5, LEN(TRIM(F37))-LEN(SUBSTITUTE(TRIM(F37),",",""))+1, 0)) -> 0 | H37: =IF(ISNUMBER(SEARCH($F$2, $F37)), 1, 0) + IF(ISNUMBER(SEARCH($F$2-1, $F37)), 1, 0) + IF(ISNUMBER(SEARCH($F$2-2, $F37)), 1, 0) + IF(ISNUMBER(SEARCH($F$2-3, $F37)), 1, 0) + IF(ISNUMBER(SEARCH($F$2-4, $F37)), 1, 0) -> 0 | I37: =IF(ISNUMBER(SEARCH($F$2, $F37)), 1, 0) + IF(ISNUMBER(SEARCH($F$2-1, $F37)), 1, 0) + IF(ISNUMBER(SEARCH($F$2-2, $F37)), 1, 0) + IF(ISNUMBER(SEARCH($F$2-3, $F37)), 1, 0) + IF(ISNUMBER(SEARCH($F$2-4, $F37)), 1, 0) + IF(ISNUMBER(SEARCH($F$2-5, $F37)), 1, 0) + IF(ISNUMBER(SEARCH($F$2-6, $F37)), 1, 0) + IF(ISNUMBER(SEARCH($F$2-7, $F37)), 1, 0) + IF(ISNUMBER(SEARCH($F$2-8, $F37)), 1, 0) + IF(ISNUMBER(SEARCH($F$2-9, $F37)), 1, 0) -> 0 | J37: =IF(F37="NA", "NA", IF(G37>0, 1, 0)) -> 0 | K37: =IF(F37="NA","NA",IF(H37>2,1,IF(H37>1,0.5,0))) -> 0 | L37: =IF(F37="NA","NA",IF(I37>5, 1, IF(I37>2, 0.5, 0))) -> 0 | M37: =SUMIF(J37:L37,"<>#N/A") -> 0 | N37: =IF(F37 = "NA", "NA", 0) -> 0 | O37: =IF(F37 = "NA", "NA", 0) -> 0 | P37: =IF(F37 = "NA", "NA", 0) -> 0 | Q37: =IF(F37 = "NA", "NA", 0) -> 0 | R37: =IF(F37 = "NA", "NA", 0) -> 0 | S37: =SUMIF(N37:R37,"<>#N/A") -> 0
A38: MA.GDP.FFR.013 | E38: ii. By Sector/ Industry | G38: =IF(LEN(TRIM(F38)) = 4, 1, IF(LEN(TRIM(F38)) > 5, LEN(TRIM(F38))-LEN(SUBSTITUTE(TRIM(F38),",",""))+1, 0)) -> 0 | H38: =IF(ISNUMBER(SEARCH($F$2, $F38)), 1, 0) + IF(ISNUMBER(SEARCH($F$2-1, $F38)), 1, 0) + IF(ISNUMBER(SEARCH($F$2-2, $F38)), 1, 0) + IF(ISNUMBER(SEARCH($F$2-3, $F38)), 1, 0) + IF(ISNUMBER(SEARCH($F$2-4, $F38)), 1, 0) -> 0 | I38: =IF(ISNUMBER(SEARCH($F$2, $F38)), 1, 0) + IF(ISNUMBER(SEARCH($F$2-1, $F38)), 1, 0) + IF(ISNUMBER(SEARCH($F$2-2, $F38)), 1, 0) + IF(ISNUMBER(SEARCH($F$2-3, $F38)), 1, 0) + IF(ISNUMBER(SEARCH($F$2-4, $F38)), 1, 0) + IF(ISNUMBER(SEARCH($F$2-5, $F38)), 1, 0) + IF(ISNUMBER(SEARCH($F$2-6, $F38)), 1, 0) + IF(ISNUMBER(SEARCH($F$2-7, $F38)), 1, 0) + IF(ISNUMBER(SEARCH($F$2-8, $F38)), 1, 0) + IF(ISNUMBER(SEARCH($F$2-9, $F38)), 1, 0) -> 0 | J38: =IF(F38="NA", "NA", IF(G38>0, 1, 0)) -> 0 | K38: =IF(F38="NA","NA",IF(H38>2,1,IF(H38>1,0.5,0))) -> 0 | L38: =IF(F38="NA","NA",IF(I38>5, 1, IF(I38>2, 0.5, 0))) -> 0 | M38: =SUMIF(J38:L38,"<>#N/A") -> 0 | N38: =IF(F38 = "NA", "NA", 0) -> 0 | O38: =IF(F38 = "NA", "NA", 0) -> 0 | P38: =IF(F38 = "NA", "NA", 0) -> 0 | Q38: =IF(F38 = "NA", "NA", 0) -> 0 | R38: =IF(F38 = "NA", "NA", 0) -> 0 | S38: =SUMIF(N38:R38,"<>#N/A") -> 0
A39: MA.GDP.GPP.000 | D39: GDP Growth Rate at Constant Prices (1) | G39: =IF(LEN(TRIM(F39)) = 4, 1, IF(LEN(TRIM(F39)) > 5, LEN(TRIM(F39))-LEN(SUBSTITUTE(TRIM(F39),",",""))+1, 0)) -> 0 | H39: =IF(ISNUMBER(SEARCH($F$2, $F39)), 1, 0) + IF(ISNUMBER(SEARCH($F$2-1, $F39)), 1, 0) + IF(ISNUMBER(SEARCH($F$2-2, $F39)), 1, 0) + IF(ISNUMBER(SEARCH($F$2-3, $F39)), 1, 0) + IF(ISNUMBER(SEARCH($F$2-4, $F39)), 1, 0) -> 0 | I39: =IF(ISNUMBER(SEARCH($F$2, $F39)), 1, 0) + IF(ISNUMBER(SEARCH($F$2-1, $F39)), 1, 0) + IF(ISNUMBER(SEARCH($F$2-2, $F39)), 1, 0) + IF(ISNUMBER(SEARCH($F$2-3, $F39)), 1, 0) + IF(ISNUMBER(SEARCH($F$2-4, $F39)), 1, 0) + IF(ISNUMBER(SEARCH($F$2-5, $F39)), 1, 0) + IF(ISNUMBER(SEARCH($F$2-6, $F39)), 1, 0) + IF(ISNUMBER(SEARCH($F$2-7, $F39)), 1, 0) + IF(ISNUMBER(SEARCH($F$2-8, $F39)), 1, 0) + IF(ISNUMBER(SEARCH($F$2-9, $F39)), 1, 0) -> 0 | J39: =IF(F39="NA", "NA", IF(G39>0, 1, 0)) -> 0 | K39: =IF(F39="NA","NA",IF(H39>2,1,IF(H39>1,0.5,0))) -> 0 | L39: =IF(F39="NA","NA",IF(I39>5, 1, IF(I39>2, 0.5, 0))) -> 0 | M39: =SUMIF(J39:L39,"<>#N/A") -> 0 | N39: =IF(F39 = "NA", "NA", 0) -> 0 | O39: =IF(F39 = "NA", "NA", 0) -> 0 | P39: =IF(F39 = "NA", "NA", 0) -> 0 | Q39: =IF(F39 = "NA", "NA", 0) -> 0 | R39: =IF(F39 = "NA", "NA", 0) -> 0 | S39: =SUMIF(N39:R39,"<>#N/A") -> 0
A40: MA.GDP.GRR.000 | D40: GDP Per Capita at Current Prices (1) | G40: =IF(LEN(TRIM(F40)) = 4, 1, IF(LEN(TRIM(F40)) > 5, LEN(TRIM(F40))-LEN(SUBSTITUTE(TRIM(F40),",",""))+1, 0)) -> 0 | H40: =IF(ISNUMBER(SEARCH($F$2, $F40)), 1, 0) + IF(ISNUMBER(SEARCH($F$2-1, $F40)), 1, 0) + IF(ISNUMBER(SEARCH($F$2-2, $F40)), 1, 0) + IF(ISNUMBER(SEARCH($F$2-3, $F40)), 1, 0) + IF(ISNUMBER(SEARCH($F$2-4, $F40)), 1, 0) -> 0 | I40: =IF(ISNUMBER(SEARCH($F$2, $F40)), 1, 0) + IF(ISNUMBER(SEARCH($F$2-1, $F40)), 1, 0) + IF(ISNUMBER(SEARCH($F$2-2, $F40)), 1, 0) + IF(ISNUMBER(SEARCH($F$2-3, $F40)), 1, 0) + IF(ISNUMBER(SEARCH($F$2-4, $F40)), 1, 0) + IF(ISNUMBER(SEARCH($F$2-5, $F40)), 1, 0) + IF(ISNUMBER(SEARCH($F$2-6, $F40)), 1, 0) + IF(ISNUMBER(SEARCH($F$2-7, $F40)), 1, 0) + IF(ISNUMBER(SEARCH($F$2-8, $F40)), 1, 0) + IF(ISNUMBER(SEARCH($F$2-9, $F40)), 1, 0) -> 0 | J40: =IF(F40="NA", "NA", IF(G40>0, 1, 0)) -> 0 | K40: =IF(F40="NA","NA",IF(H40>2,1,IF(H40>1,0.5,0))) -> 0 | L40: =IF(F40="NA","NA",IF(I40>5, 1, IF(I40>2, 0.5, 0))) -> 0 | M40: =SUMIF(J40:L40,"<>#N/A") -> 0 | N40: =IF(F40 = "NA", "NA", 0) -> 0 | O40: =IF(F40 = "NA", "NA", 0) -> 0 | P40: =IF(F40 = "NA", "NA", 0) -> 0 | Q40: =IF(F40 = "NA", "NA", 0) -> 0 | R40: =IF(F40 = "NA", "NA", 0) -> 0 | S40: =SUMIF(N40:R40,"<>#N/A") -> 0
...

Sheet Summary Report
B1: ACSS Open Data Score
B3: ASEAN Member States
B4: Sections | C4: Coverage | F4: Opennes | I4: Overall Score
C5: Max Score | D5: Actual Score | E5: Sub Score | F5: Max Score | G5: Actual Score | H5: Sub Score
B6: (A) Social-Demography | C6: =(32-Input!D93)*3 -> 96 | D6: =SUM(Input!M$5:M$36) -> 0 | E6: =(D6/C6)*100% -> 0 | F6: =(32-Input!D93)*5 -> 160 | G6: =SUM(Input!S$5:S$36) -> 0 | H6: =(G6/F6)*100% -> 0 | I6: =(D6/C6)*50%+(G6/F6)*50% -> 0
B7: (B) Macroeconomic | C7: =(14-Input!D94)*3 -> 42 | D7: =SUM(Input!M$37:M$50) -> 0 | E7: =(D7/C7)*100% -> 0 | F7: =(14-Input!D94)*5 -> 70 | G7: =SUM(Input!S$37:S$50) -> 0 | H7: =(G7/F7)*100% -> 0 | I7: =(D7/C7)*50%+(G7/F7)*50% -> 0
B8: (C) Trade & Investment | C8: =(15-Input!D95)*3 -> 33 | D8: =SUM(Input!M$51:M$65)-Input!M55-Input!M61-Input!M65 -> 0 | E8: =(D8/C8)*100% -> 0 | F8: =(15-Input!D95)*5 -> 55 | G8: =SUM(Input!S$51:S$65)-Input!S55-Input!S61-Input!S65 -> 0 | H8: =(G8/F8)*100% -> 0 | I8: =(D8/C8)*50%+(G8/F8)*50% -> 0
B9: (D) Connectivity & Environment | C9: =(16-Input!D96)*3 -> 45 | D9: =SUM(Input!M$66:M$81)-Input!M68 -> 0 | E9: =(D9/C9)*100% -> 0 | F9: =(16-Input!D96)*5 -> 75 | G9: =SUM(Input!S$66:S$81)-Input!S68 -> 0 | H9: =(G9/F9)*100% -> 0 | I9: =(D9/C9)*50%+(G9/F9)*50% -> 0
B10: Weighted Score | C10: Coverage weighted sub score: | E10: =(D6/C6)*25%+(D7/C7)*25%+ (D8/C8)*25% + (D9/C9)*25% -> 0 | F10: Opennes weighted sub score: | H10: =(G6/F6)*25%+(G7/F7)*25%+ (G8/F8)*25% + (G9/F9)*25% -> 0 | I10: =(E10*50%)+(H10*50%) -> 0
B13: Max coverage score = number of indicator and disaggregation * 3
B14: Max openness score = number of indicator and disaggregation * 5

Sheet Scoring Guideline
B2: Coverage Scoring Guidelines
B4: C1 - Disaggregation
B5: Point | D5: Condition | E5: Notes
B6: 1 | C6: Point | D6: if the published data and its required disaggregation/ breakdown are available. | E6: Indicator(s) that are not applicable to the AMS will be excluded from country assessment for all elements of coverage and openness. E.g., i.Indicators with the disaggregation ‘Intra and Extra’ is applicable to ASEANStats only. AMSs will not be assessed for these indicators for all elements of Coverage and Openness. ii.‘Proportion of Population Living below National Poverty Line’ is not applicable to Brunei Darussalam and Singapore and will not be assessed for these indicators for all elements of Coverage and Openness.
B7: 0 | C7: Point | D7: if the published data and its required disaggregation/ breakdown are NOT available.
B8: Indicator(s) that scored 0 for C1 will be awarded 0 point for all data elements of coverage and openness (i.e., C1-C3 and O1-O5)
B10: C2 – Availability of Data for Last 5 Years
B11: Point | D11: Condition | E11: Notes
B12: 1 | C12: Point | D12: if the published data and its required disaggregation/ breakdown are available for at least 3 of the last 5 years. | E12: E.g., the 3 years must occur within 2013-2017 (or 2012/2013-2016/2017). If the indicator shows data for a non-calendar year (i.e. 2012/2013), this should be counted as one year. Overlapping years (such as 2013 and 2013/14 for a single indicator) should not be double counted.
B13: 0.5 | C13: Point | D13: if the published data and its required disaggregation/ breakdown are available for 1 or 2 of the last 5 years. | E13: E.g., the 1-2 years must occur within 2013-2017 (or 2012/2013-2016/2017). If the indicator shows data for a non-calendar year (i.e. 2013/2014), this should be counted as one year.
B14: 0 | C14: Point | D14: if the published data and its required disaggregation/ breakdown are NOT available.
B16: C3 – Availability of Data for Last 10 Years
B17: Point | D17: Condition | E17: Notes
B18: 1 | C18: Point | D18: if the published data and its required disaggregation/ breakdown are available for at least 6 of the last 10 years. | E18: E.g., the 6 years must occur within 2008-2017 (or 2007/2008-2016/2017). If the indicator shows data for a non-calendar year (i.e. 2013/2014), this should be counted as one year. Overlapping years (2013 and 2013/14) should not be double counted.
B19: 0.5 | C19: Point | D19: if the published data and its required disaggregation/ breakdown are available for 3 to 5 of the last 10 years. | E19: E.g., the 3-5 years must occur within 2007-2016 (or 2007/2008-2016/2017). If the indicator shows data for a non-calendar year (i.e. 2013/2014), this should be counted as one year. Overlapping years (2013 and 2013/14) should not be double counted.
B20: 0 | C20: Point | D20: if the published data and its required disaggregation/ breakdown are available for 2 or fewer of the last 10 years.
B24: Openness Scoring Guidelines
B26: O1 – Machine Readability
B27: Point | D27: Condition | E27: Notes
B28: 1 | C28: Point | D28: if the published data and its required disaggregation/ breakdown are available in machine readable format (such as XLSX, CSV, TXT, JSON and XML). | E28: PDF document containing tables of data are not machine-readable because a computer would struggle to access the tabular information. The equivalent tables in a format such as a spreadsheet would be machine readable. As another example scans (photographs) of text are not machine-readable but the equivalent text in a format such as a simple ASCII text file can machine readable and processable. If published data are available in both machine readable and non-machine readable formats, a full point should be awarded for machine readability
B29: 0 | C29: Point | D29: if all published data and its required disaggregation/ breakdown are not available in machine-readable format.
B32: O2 – Non-Proprietary
B33: Point | D33: Condition | E33: Notes
B34: 1 | C34: Point | D34: if the published data and its required disaggregation/ breakdown are available in non-proprietary format (such as XLSX, CSV, XML, TXT and JSON). | E34: XLS, Stata, SAS, SPSS, DOC and PPT files are proprietary. If published data are available in both proprietary and non-proprietary formats, a full point would be awarded.
B35: 0 | C35: Point | D35: if the published data and its required disaggregation/ breakdown are not available in non-proprietary format | E35: A zero point is only given if no data in a data category is available in this format or if all data files are compressed in RAR format. ZIP compression is non-proprietary and does not affect score.
B38: O3 – Download Options
B39: Point | D39: Condition | E39: Notes
B40: 1 | C40: Point | D40: if the website containing the published data and its required disaggregation/ breakdown has a bulk download option AND an API or user-selectable download option. | E40: Assessment is based on the ability to bulk download on the NSO’s website or line ministries’ website (linked from NSO’s website).
B41: 0.5 | C41: Point | D41: if the website containing the published data and its required disaggregation/ breakdown has an API, bulk download, or user-selectable download options. | E41: Assessment is based on the ability to bulk download on the NSO’s website or line ministries’ website (linked from NSO’s website).
B42: 0 | C42: Point | D42: if the website containing the published data and its required disaggregation/ breakdown does not have any API, bulk download, or user-selectable download options. | E42: Assessment is based on the ability to bulk download on the NSO’s website or line ministries’ website (linked from NSO’s website).
B45: O4 – Metadata Availability
B46: Point | D46: Condition | E46: Notes
B47: 1 | C47: Point | D47: if the published data and its required disaggregation/ breakdown has all metadata fields. | E47: Full point if metadata contains all of the following fields in line with the Concept Note on ACSS Open Data Initiative on Statistics adopted at ACSS8. a.definition; b.frequency; c.unit of measure; d.level of disaggregation; e.data source; f.availability (start & end periods); g.URL for direct access to data series/ statistical table; h.formats for download; and i.URL to terms of use Metadata may be included in the same file as data or it can be included elsewhere on the NSO website (this may happen if data are in a regularly published report, survey, or census).
B48: 0.5 | C48: Point | D48: if the published data and its required disaggregation/ breakdown has at least 5 of the metadata fields. | E48: Half a point if metadata contains at least 5 of the fields a to i as listed above.
B49: 0 | C49: Point | D49: if the published data and its required disaggregation/ breakdown has 4 or less of the metadata fields.
B52: O5 – Term of Use
B53: Point | D53: Condition | E53: Notes
B54: 1 | C54: Point | D54: if the website containing the published data and its required disaggregation/ breakdown has a terms of use classified as open. | E54: AMSs may refer to the ODIN’s Terms of Use score for their respective website. Full point if their website TOUs is considered “Fully Open”.
B55: 0.5 | C55: Point | D55: if the website containing the published data and its required disaggregation/ breakdown has a terms of use classified as semi-restrictive. | E55: AMSs may refer to the ODIN’s Terms of Use score for their respective website. Half a point if their website TOUs is considered “Semi-restrictive”.
B56: 0 | C56: Point | D56: if the website containing the published data and its required disaggregation/ breakdown has a terms of use classified as restrictive or does not have any terms of use. | E56: AMSs may refer to the ODIN’s Terms of Use score for their respective website. Zero point if their website TOUs is considered “Restrictive”.

Sheet Sheet1
A1: Not Available | B1: Not applicable | C1: Machine Readability | D1: Non-Proprietary | E1: Download Options | F1: Metadata Availability | G1: Terms of Use
A2: 0 | B2: NA | C2: 0 | D2: 0 | E2: 0 | F2: 0 | G2: 0
C3: 1 | D3: 1 | E3: 0.5 | F3: 0.5 | G3: 0.5
E4: 1 | F4: 1 | G4: 1
